Workbook
Name ItemList: OFFSET('Master Stok'!$A$5,0,0,COUNTA('Master Stok'!$A$5:$A$1000),1)
Name OutletList: Referensi!$A$2:$A$20

Sheet Beranda
A1: ITEM OUTLET DASHBOARD
A3: Klik nama outlet untuk buka riwayat pengambilan barang. Input transaksi cukup dari sheet Input Transaksi, lalu stok sisa dan sheet outlet akan update otomatis.
A5: Total Item Aktif | B5: =COUNTA('Master Stok'!$A$5:$A$1000) | D5: Total Stok Awal | E5: =SUM('Master Stok'!$B$5:$B$1000) | G5: Total Keluar | H5: =SUM('Master Stok'!$C$5:$C$1000)
A7: Sisa Stok | B7: =SUM('Master Stok'!$D$5:$D$1000) | D7: 1. Isi item dan stok awal di Master Stok. 2. Input pengambilan di Input Transaksi. 3. Klik nama outlet untuk lihat riwayatnya.
A10: OUTLET SELATAN | D10: OUTLET UTARA | G10: OUTLET BARAT
A11: JCL SIDAKARYA | D11: JCL AYANI | G11: JCL NUSA KAMBANGAN
A12: BALI WASH GALANG | D12: CUCI DEWE | G12: JCL MERPATI
A13: JCL BYPASS | D13: LONDRI DEWE ANTASURA | G13: BALI WASH
A14: JCL SESETAN | D14: GEDE LONDRI | G14: RINJANI WASH
A15: CL SESETAN | G15: MONANG MANING
A16: GRIYA ANYAR
A17: KLIN WASH
A18: LONDRI DEWE
A19: DIY
A20: JCL PEMOGAN

Sheet Master Stok
A1: MASTER STOK
A2: Ubah daftar item dan stok awal sesuai kebutuhan. Tambahkan item baru berurutan ke bawah tanpa sel kosong supaya dropdown dan total tetap ikut.
A4: Item | B4: Stok Awal | C4: Total Keluar | D4: Sisa Stok
A5: SODA | C5: =IF(A5="","",SUMIFS('Input Transaksi'!$E$5:$E$5000,'Input Transaksi'!$D$5:$D$5000,A5)) | D5: =IF(OR(A5="",B5=""),"",B5-C5)
A6: CITRUN | C6: =IF(A6="","",SUMIFS('Input Transaksi'!$E$5:$E$5000,'Input Transaksi'!$D$5:$D$5000,A6)) | D6: =IF(OR(A6="",B6=""),"",B6-C6)
A7: SAPU | C7: =IF(A7="","",SUMIFS('Input Transaksi'!$E$5:$E$5000,'Input Transaksi'!$D$5:$D$5000,A7)) | D7: =IF(OR(A7="",B7=""),"",B7-C7)
A8: SUNLIGHT | C8: =IF(A8="","",SUMIFS('Input Transaksi'!$E$5:$E$5000,'Input Transaksi'!$D$5:$D$5000,A8)) | D8: =IF(OR(A8="",B8=""),"",B8-C8)
A9: SIKAT MESIN | C9: =IF(A9="","",SUMIFS('Input Transaksi'!$E$5:$E$5000,'Input Transaksi'!$D$5:$D$5000,A9)) | D9: =IF(OR(A9="",B9=""),"",B9-C9)
A10: KUAS | C10: =IF(A10="","",SUMIFS('Input Transaksi'!$E$5:$E$5000,'Input Transaksi'!$D$5:$D$5000,A10)) | D10: =IF(OR(A10="",B10=""),"",B10-C10)
A11: KRESEK SAMPAH | C11: =IF(A11="","",SUMIFS('Input Transaksi'!$E$5:$E$5000,'Input Transaksi'!$D$5:$D$5000,A11)) | D11: =IF(OR(A11="",B11=""),"",B11-C11)
A12: SIKAT KAWAT | C12: =IF(A12="","",SUMIFS('Input Transaksi'!$E$5:$E$5000,'Input Transaksi'!$D$5:$D$5000,A12)) | D12: =IF(OR(A12="",B12=""),"",B12-C12)
A13: SAPU LIDI | C13: =IF(A13="","",SUMIFS('Input Transaksi'!$E$5:$E$5000,'Input Transaksi'!$D$5:$D$5000,A13)) | D13: =IF(OR(A13="",B13=""),"",B13-C13)
A14: SEMPROTAN | C14: =IF(A14="","",SUMIFS('Input Transaksi'!$E$5:$E$5000,'Input Transaksi'!$D$5:$D$5000,A14)) | D14: =IF(OR(A14="",B14=""),"",B14-C14)
A15: SAPU LANTAI | C15: =IF(A15="","",SUMIFS('Input Transaksi'!$E$5:$E$5000,'Input Transaksi'!$D$5:$D$5000,A15)) | D15: =IF(OR(A15="",B15=""),"",B15-C15)
A16: SUPER PEL | C16: =IF(A16="","",SUMIFS('Input Transaksi'!$E$5:$E$5000,'Input Transaksi'!$D$5:$D$5000,A16)) | D16: =IF(OR(A16="",B16=""),"",B16-C16)
... A34: KESET LANTAI | C34: =IF(A34="","",SUMIFS('Input Transaksi'!$E$5:$E$5000,'Input Transaksi'!$D$5:$D$5000,A34)) | D34: =IF(OR(A34="",B34=""),"",B34-C34)
C35: =IF(A35="","",SUMIFS('Input Transaksi'!$E$5:$E$5000,'Input Transaksi'!$D$5:$D$5000,A35)) | D35: =IF(OR(A35="",B35=""),"",B35-C35)
C36: =IF(A36="","",SUMIFS('Input Transaksi'!$E$5:$E$5000,'Input Transaksi'!$D$5:$D$5000,A36)) | D36: =IF(OR(A36="",B36=""),"",B36-C36)
C37: =IF(A37="","",SUMIFS('Input Transaksi'!$E$5:$E$5000,'Input Transaksi'!$D$5:$D$5000,A37)) | D37: =IF(OR(A37="",B37=""),"",B37-C37)
C38: =IF(A38="","",SUMIFS('Input Transaksi'!$E$5:$E$5000,'Input Transaksi'!$D$5:$D$5000,A38)) | D38: =IF(OR(A38="",B38=""),"",B38-C38)
C39: =IF(A39="","",SUMIFS('Input Transaksi'!$E$5:$E$5000,'Input Transaksi'!$D$5:$D$5000,A39)) | D39: =IF(OR(A39="",B39=""),"",B39-C39)
C40: =IF(A40="","",SUMIFS('Input Transaksi'!$E$5:$E$5000,'Input Transaksi'!$D$5:$D$5000,A40)) | D40: =IF(OR(A40="",B40=""),"",B40-C40)
C41: =IF(A41="","",SUMIFS('Input Transaksi'!$E$5:$E$5000,'Input Transaksi'!$D$5:$D$5000,A41)) | D41: =IF(OR(A41="",B41=""),"",B41-C41)
C42: =IF(A42="","",SUMIFS('Input Transaksi'!$E$5:$E$5000,'Input Transaksi'!$D$5:$D$5000,A42)) | D42: =IF(OR(A42="",B42=""),"",B42-C42)
C43: =IF(A43="","",SUMIFS('Input Transaksi'!$E$5:$E$5000,'Input Transaksi'!$D$5:$D$5000,A43)) | D43: =IF(OR(A43="",B43=""),"",B43-C43)
C44: =IF(A44="","",SUMIFS('Input Transaksi'!$E$5:$E$5000,'Input Transaksi'!$D$5:$D$5000,A44)) | D44: =IF(OR(A44="",B44=""),"",B44-C44)
C45: =IF(A45="","",SUMIFS('Input Transaksi'!$E$5:$E$5000,'Input Transaksi'!$D$5:$D$5000,A45)) | D45: =IF(OR(A45="",B45=""),"",B45-C45)
C46: =IF(A46="","",SUMIFS('Input Transaksi'!$E$5:$E$5000,'Input Transaksi'!$D$5:$D$5000,A46)) | D46: =IF(OR(A46="",B46=""),"",B46-C46)
... C1000: =IF(A1000="","",SUMIFS('Input Transaksi'!$E$5:$E$5000,'Input Transaksi'!$D$5:$D$5000,A1000)) | D1000: =IF(OR(A1000="",B1000=""),"",B1000-C1000)

Sheet Input Transaksi
A1: INPUT TRANSAKSI
A2: Isi tanggal, outlet, item, qty keluar, dan catatan seperlunya. Kolom wilayah terisi otomatis dari daftar outlet.
A4: Tanggal | B4: Outlet | C4: Wilayah | D4: Item | E4: Qty Keluar | F4: Catatan
C5: =IF(B5="","",IFERROR(VLOOKUP(B5,'Daftar Outlet'!$A$4:$B$22,2,FALSE),""))
C6: =IF(B6="","",IFERROR(VLOOKUP(B6,'Daftar Outlet'!$A$4:$B$22,2,FALSE),""))
C7: =IF(B7="","",IFERROR(VLOOKUP(B7,'Daftar Outlet'!$A$4:$B$22,2,FALSE),""))
C8: =IF(B8="","",IFERROR(VLOOKUP(B8,'Daftar Outlet'!$A$4:$B$22,2,FALSE),""))
C9: =IF(B9="","",IFERROR(VLOOKUP(B9,'Daftar Outlet'!$A$4:$B$22,2,FALSE),""))
C10: =IF(B10="","",IFERROR(VLOOKUP(B10,'Daftar Outlet'!$A$4:$B$22,2,FALSE),""))
C11: =IF(B11="","",IFERROR(VLOOKUP(B11,'Daftar Outlet'!$A$4:$B$22,2,FALSE),""))
C12: =IF(B12="","",IFERROR(VLOOKUP(B12,'Daftar Outlet'!$A$4:$B$22,2,FALSE),""))
C13: =IF(B13="","",IFERROR(VLOOKUP(B13,'Daftar Outlet'!$A$4:$B$22,2,FALSE),""))
C14: =IF(B14="","",IFERROR(VLOOKUP(B14,'Daftar Outlet'!$A$4:$B$22,2,FALSE),""))
C15: =IF(B15="","",IFERROR(VLOOKUP(B15,'Daftar Outlet'!$A$4:$B$22,2,FALSE),""))
C16: =IF(B16="","",IFERROR(VLOOKUP(B16,'Daftar Outlet'!$A$4:$B$22,2,FALSE),""))
... C5000: =IF(B5000="","",IFERROR(VLOOKUP(B5000,'Daftar Outlet'!$A$4:$B$22,2,FALSE),""))

Sheet Daftar Outlet
A1: DAFTAR OUTLET
A2: Daftar ini dipakai untuk dropdown outlet dan penentuan wilayah otomatis.
A3: Outlet | B3: Wilayah | C3: Buka Sheet
A4: JCL SIDAKARYA | B4: SELATAN | C4: Buka
A5: BALI WASH GALANG | B5: SELATAN | C5: Buka
A6: JCL BYPASS | B6: SELATAN | C6: Buka
A7: JCL SESETAN | B7: SELATAN | C7: Buka
A8: CL SESETAN | B8: SELATAN | C8: Buka
A9: GRIYA ANYAR | B9: SELATAN | C9: Buka
A10: KLIN WASH | B10: SELATAN | C10: Buka
A11: LONDRI DEWE | B11: SELATAN | C11: Buka
A12: DIY | B12: SELATAN | C12: Buka
A13: JCL PEMOGAN | B13: SELATAN | C13: Buka
A14: JCL AYANI | B14: UTARA | C14: Buka
... A22: MONANG MANING | B22: BARAT | C22: Buka

Sheet JCL SIDAKARYA
A1: JCL SIDAKARYA | F1: Kembali ke Beranda
A2: Wilayah | B2: SELATAN | C2: Total Qty | D2: =SUMIFS('Input Transaksi'!$E$5:$E$5000,'Input Transaksi'!$B$5:$B$5000,"JCL SIDAKARYA") | E2: Jumlah Transaksi | F2: =COUNTIF('Input Transaksi'!$B$5:$B$5000,"JCL SIDAKARYA")
A4: Tanggal | B4: Item | C4: Qty Keluar | D4: Catatan | E4: RowRef
A5: =IF($E5="","",INDEX('Input Transaksi'!$A:$A,$E5)) | B5: =IF($E5="","",INDEX('Input Transaksi'!$D:$D,$E5)) | C5: =IF($E5="","",INDEX('Input Transaksi'!$E:$E,$E5)) | D5: =IF($E5="","",INDEX('Input Transaksi'!$F:$F,$E5)) | E5: =IFERROR(AGGREGATE(15,6,ROW('Input Transaksi'!$B$5:$B$5000)/('Input Transaksi'!$B$5:$B$5000="JCL SIDAKARYA"),ROWS($E$5:E5)),"")
A6: =IF($E6="","",INDEX('Input Transaksi'!$A:$A,$E6)) | B6: =IF($E6="","",INDEX('Input Transaksi'!$D:$D,$E6)) | C6: =IF($E6="","",INDEX('Input Transaksi'!$E:$E,$E6)) | D6: =IF($E6="","",INDEX('Input Transaksi'!$F:$F,$E6)) | E6: =IFERROR(AGGREGATE(15,6,ROW('Input Transaksi'!$B$5:$B$5000)/('Input Transaksi'!$B$5:$B$5000="JCL SIDAKARYA"),ROWS($E$5:E6)),"")
A7: =IF($E7="","",INDEX('Input Transaksi'!$A:$A,$E7)) | B7: =IF($E7="","",INDEX('Input Transaksi'!$D:$D,$E7)) | C7: =IF($E7="","",INDEX('Input Transaksi'!$E:$E,$E7)) | D7: =IF($E7="","",INDEX('Input Transaksi'!$F:$F,$E7)) | E7: =IFERROR(AGGREGATE(15,6,ROW('Input Transaksi'!$B$5:$B$5000)/('Input Transaksi'!$B$5:$B$5000="JCL SIDAKARYA"),ROWS($E$5:E7)),"")
A8: =IF($E8="","",INDEX('Input Transaksi'!$A:$A,$E8)) | B8: =IF($E8="","",INDEX('Input Transaksi'!$D:$D,$E8)) | C8: =IF($E8="","",INDEX('Input Transaksi'!$E:$E,$E8)) | D8: =IF($E8="","",INDEX('Input Transaksi'!$F:$F,$E8)) | E8: =IFERROR(AGGREGATE(15,6,ROW('Input Transaksi'!$B$5:$B$5000)/('Input Transaksi'!$B$5:$B$5000="JCL SIDAKARYA"),ROWS($E$5:E8)),"")
A9: =IF($E9="","",INDEX('Input Transaksi'!$A:$A,$E9)) | B9: =IF($E9="","",INDEX('Input Transaksi'!$D:$D,$E9)) | C9: =IF($E9="","",INDEX('Input Transaksi'!$E:$E,$E9)) | D9: =IF($E9="","",INDEX('Input Transaksi'!$F:$F,$E9)) | E9: =IFERROR(AGGREGATE(15,6,ROW('Input Transaksi'!$B$5:$B$5000)/('Input Transaksi'!$B$5:$B$5000="JCL SIDAKARYA"),ROWS($E$5:E9)),"")
A10: =IF($E10="","",INDEX('Input Transaksi'!$A:$A,$E10)) | B10: =IF($E10="","",INDEX('Input Transaksi'!$D:$D,$E10)) | C10: =IF($E10="","",INDEX('Input Transaksi'!$E:$E,$E10)) | D10: =IF($E10="","",INDEX('Input Transaksi'!$F:$F,$E10)) | E10: =IFERROR(AGGREGATE(15,6,ROW('Input Transaksi'!$B$5:$B$5000)/('Input Transaksi'!$B$5:$B$5000="JCL SIDAKARYA"),ROWS($E$5:E10)),"")
A11: =IF($E11="","",INDEX('Input Transaksi'!$A:$A,$E11)) | B11: =IF($E11="","",INDEX('Input Transaksi'!$D:$D,$E11)) | C11: =IF($E11="","",INDEX('Input Transaksi'!$E:$E,$E11)) | D11: =IF($E11="","",INDEX('Input Transaksi'!$F:$F,$E11)) | E11: =IFERROR(AGGREGATE(15,6,ROW('Input Transaksi'!$B$5:$B$5000)/('Input Transaksi'!$B$5:$B$5000="JCL SIDAKARYA"),ROWS($E$5:E11)),"")
A12: =IF($E12="","",INDEX('Input Transaksi'!$A:$A,$E12)) | B12: =IF($E12="","",INDEX('Input Transaksi'!$D:$D,$E12)) | C12: =IF($E12="","",INDEX('Input Transaksi'!$E:$E,$E12)) | D12: =IF($E12="","",INDEX('Input Transaksi'!$F:$F,$E12)) | E12: =IFERROR(AGGREGATE(15,6,ROW('Input Transaksi'!$B$5:$B$5000)/('Input Transaksi'!$B$5:$B$5000="JCL SIDAKARYA"),ROWS($E$5:E12)),"")
A13: =IF($E13="","",INDEX('Input Transaksi'!$A:$A,$E13)) | B13: =IF($E13="","",INDEX('Input Transaksi'!$D:$D,$E13)) | C13: =IF($E13="","",INDEX('Input Transaksi'!$E:$E,$E13)) | D13: =IF($E13="","",INDEX('Input Transaksi'!$F:$F,$E13)) | E13: =IFERROR(AGGREGATE(15,6,ROW('Input Transaksi'!$B$5:$B$5000)/('Input Transaksi'!$B$5:$B$5000="JCL SIDAKARYA"),ROWS($E$5:E13)),"")
A14: =IF($E14="","",INDEX('Input Transaksi'!$A:$A,$E14)) | B14: =IF($E14="","",INDEX('Input Transaksi'!$D:$D,$E14)) | C14: =IF($E14="","",INDEX('Input Transaksi'!$E:$E,$E14)) | D14: =IF($E14="","",INDEX('Input Transaksi'!$F:$F,$E14)) | E14: =IFERROR(AGGREGATE(15,6,ROW('Input Transaksi'!$B$5:$B$5000)/('Input Transaksi'!$B$5:$B$5000="JCL SIDAKARYA"),ROWS($E$5:E14)),"")
A15: =IF($E15="","",INDEX('Input Transaksi'!$A:$A,$E15)) | B15: =IF($E15="","",INDEX('Input Transaksi'!$D:$D,$E15)) | C15: =IF($E15="","",INDEX('Input Transaksi'!$E:$E,$E15)) | D15: =IF($E15="","",INDEX('Input Transaksi'!$F:$F,$E15)) | E15: =IFERROR(AGGREGATE(15,6,ROW('Input Transaksi'!$B$5:$B$5000)/('Input Transaksi'!$B$5:$B$5000="JCL SIDAKARYA"),ROWS($E$5:E15)),"")
A16: =IF($E16="","",INDEX('Input Transaksi'!$A:$A,$E16)) | B16: =IF($E16="","",INDEX('Input Transaksi'!$D:$D,$E16)) | C16: =IF($E16="","",INDEX('Input Transaksi'!$E:$E,$E16)) | D16: =IF($E16="","",INDEX('Input Transaksi'!$F:$F,$E16)) | E16: =IFERROR(AGGREGATE(15,6,ROW('Input Transaksi'!$B$5:$B$5000)/('Input Transaksi'!$B$5:$B$5000="JCL SIDAKARYA"),ROWS($E$5:E16)),"")
... A1000: =IF($E1000="","",INDEX('Input Transaksi'!$A:$A,$E1000)) | B1000: =IF($E1000="","",INDEX('Input Transaksi'!$D:$D,$E1000)) | C1000: =IF($E1000="","",INDEX('Input Transaksi'!$E:$E,$E1000)) | D1000: =IF($E1000="","",INDEX('Input Transaksi'!$F:$F,$E1000)) | E1000: =IFERROR(AGGREGATE(15,6,ROW('Input Transaksi'!$B$5:$B$5000)/('Input Transaksi'!$B$5:$B$5000="JCL SIDAKARYA"),ROWS($E$5:E1000)),"")

Sheet BALI WASH GALANG
A1: BALI WASH GALANG | F1: Kembali ke Beranda
A2: Wilayah | B2: SELATAN | C2: Total Qty | D2: =SUMIFS('Input Transaksi'!$E$5:$E$5000,'Input Transaksi'!$B$5:$B$5000,"BALI WASH GALANG") | E2: Jumlah Transaksi | F2: =COUNTIF('Input Transaksi'!$B$5:$B$5000,"BALI WASH GALANG")
A4: Tanggal | B4: Item | C4: Qty Keluar | D4: Catatan | E4: RowRef
A5: =IF($E5="","",INDEX('Input Transaksi'!$A:$A,$E5)) | B5: =IF($E5="","",INDEX('Input Transaksi'!$D:$D,$E5)) | C5: =IF($E5="","",INDEX('Input Transaksi'!$E:$E,$E5)) | D5: =IF($E5="","",INDEX('Input Transaksi'!$F:$F,$E5)) | E5: =IFERROR(AGGREGATE(15,6,ROW('Input Transaksi'!$B$5:$B$5000)/('Input Transaksi'!$B$5:$B$5000="BALI WASH GALANG"),ROWS($E$5:E5)),"")
A6: =IF($E6="","",INDEX('Input Transaksi'!$A:$A,$E6)) | B6: =IF($E6="","",INDEX('Input Transaksi'!$D:$D,$E6)) | C6: =IF($E6="","",INDEX('Input Transaksi'!$E:$E,$E6)) | D6: =IF($E6="","",INDEX('Input Transaksi'!$F:$F,$E6)) | E6: =IFERROR(AGGREGATE(15,6,ROW('Input Transaksi'!$B$5:$B$5000)/('Input Transaksi'!$B$5:$B$5000="BALI WASH GALANG"),ROWS($E$5:E6)),"")
A7: =IF($E7="","",INDEX('Input Transaksi'!$A:$A,$E7)) | B7: =IF($E7="","",INDEX('Input Transaksi'!$D:$D,$E7)) | C7: =IF($E7="","",INDEX('Input Transaksi'!$E:$E,$E7)) | D7: =IF($E7="","",INDEX('Input Transaksi'!$F:$F,$E7)) | E7: =IFERROR(AGGREGATE(15,6,ROW('Input Transaksi'!$B$5:$B$5000)/('Input Transaksi'!$B$5:$B$5000="BALI WASH GALANG"),ROWS($E$5:E7)),"")
A8: =IF($E8="","",INDEX('Input Transaksi'!$A:$A,$E8)) | B8: =IF($E8="","",INDEX('Input Transaksi'!$D:$D,$E8)) | C8: =IF($E8="","",INDEX('Input Transaksi'!$E:$E,$E8)) | D8: =IF($E8="","",INDEX('Input Transaksi'!$F:$F,$E8)) | E8: =IFERROR(AGGREGATE(15,6,ROW('Input Transaksi'!$B$5:$B$5000)/('Input Transaksi'!$B$5:$B$5000="BALI WASH GALANG"),ROWS($E$5:E8)),"")
A9: =IF($E9="","",INDEX('Input Transaksi'!$A:$A,$E9)) | B9: =IF($E9="","",INDEX('Input Transaksi'!$D:$D,$E9)) | C9: =IF($E9="","",INDEX('Input Transaksi'!$E:$E,$E9)) | D9: =IF($E9="","",INDEX('Input Transaksi'!$F:$F,$E9)) | E9: =IFERROR(AGGREGATE(15,6,ROW('Input Transaksi'!$B$5:$B$5000)/('Input Transaksi'!$B$5:$B$5000="BALI WASH GALANG"),ROWS($E$5:E9)),"")
A10: =IF($E10="","",INDEX('Input Transaksi'!$A:$A,$E10)) | B10: =IF($E10="","",INDEX('Input Transaksi'!$D:$D,$E10)) | C10: =IF($E10="","",INDEX('Input Transaksi'!$E:$E,$E10)) | D10: =IF($E10="","",INDEX('Input Transaksi'!$F:$F,$E10)) | E10: =IFERROR(AGGREGATE(15,6,ROW('Input Transaksi'!$B$5:$B$5000)/('Input Transaksi'!$B$5:$B$5000="BALI WASH GALANG"),ROWS($E$5:E10)),"")
A11: =IF($E11="","",INDEX('Input Transaksi'!$A:$A,$E11)) | B11: =IF($E11="","",INDEX('Input Transaksi'!$D:$D,$E11)) | C11: =IF($E11="","",INDEX('Input Transaksi'!$E:$E,$E11)) | D11: =IF($E11="","",INDEX('Input Transaksi'!$F:$F,$E11)) | E11: =IFERROR(AGGREGATE(15,6,ROW('Input Transaksi'!$B$5:$B$5000)/('Input Transaksi'!$B$5:$B$5000="BALI WASH GALANG"),ROWS($E$5:E11)),"")
A12: =IF($E12="","",INDEX('Input Transaksi'!$A:$A,$E12)) | B12: =IF($E12="","",INDEX('Input Transaksi'!$D:$D,$E12)) | C12: =IF($E12="","",INDEX('Input Transaksi'!$E:$E,$E12)) | D12: =IF($E12="","",INDEX('Input Transaksi'!$F:$F,$E12)) | E12: =IFERROR(AGGREGATE(15,6,ROW('Input Transaksi'!$B$5:$B$5000)/('Input Transaksi'!$B$5:$B$5000="BALI WASH GALANG"),ROWS($E$5:E12)),"")
A13: =IF($E13="","",INDEX('Input Transaksi'!$A:$A,$E13)) | B13: =IF($E13="","",INDEX('Input Transaksi'!$D:$D,$E13)) | C13: =IF($E13="","",INDEX('Input Transaksi'!$E:$E,$E13)) | D13: =IF($E13="","",INDEX('Input Transaksi'!$F:$F,$E13)) | E13: =IFERROR(AGGREGATE(15,6,ROW('Input Transaksi'!$B$5:$B$5000)/('Input Transaksi'!$B$5:$B$5000="BALI WASH GALANG"),ROWS($E$5:E13)),"")
A14: =IF($E14="","",INDEX('Input Transaksi'!$A:$A,$E14)) | B14: =IF($E14="","",INDEX('Input Transaksi'!$D:$D,$E14)) | C14: =IF($E14="","",INDEX('Input Transaksi'!$E:$E,$E14)) | D14: =IF($E14="","",INDEX('Input Transaksi'!$F:$F,$E14)) | E14: =IFERROR(AGGREGATE(15,6,ROW('Input Transaksi'!$B$5:$B$5000)/('Input Transaksi'!$B$5:$B$5000="BALI WASH GALANG"),ROWS($E$5:E14)),"")
A15: =IF($E15="","",INDEX('Input Transaksi'!$A:$A,$E15)) | B15: =IF($E15="","",INDEX('Input Transaksi'!$D:$D,$E15)) | C15: =IF($E15="","",INDEX('Input Transaksi'!$E:$E,$E15)) | D15: =IF($E15="","",INDEX('Input Transaksi'!$F:$F,$E15)) | E15: =IFERROR(AGGREGATE(15,6,ROW('Input Transaksi'!$B$5:$B$5000)/('Input Transaksi'!$B$5:$B$5000="BALI WASH GALANG"),ROWS($E$5:E15)),"")
A16: =IF($E16="","",INDEX('Input Transaksi'!$A:$A,$E16)) | B16: =IF($E16="","",INDEX('Input Transaksi'!$D:$D,$E16)) | C16: =IF($E16="","",INDEX('Input Transaksi'!$E:$E,$E16)) | D16: =IF($E16="","",INDEX('Input Transaksi'!$F:$F,$E16)) | E16: =IFERROR(AGGREGATE(15,6,ROW('Input Transaksi'!$B$5:$B$5000)/('Input Transaksi'!$B$5:$B$5000="BALI WASH GALANG"),ROWS($E$5:E16)),"")
... A1000: =IF($E1000="","",INDEX('Input Transaksi'!$A:$A,$E1000)) | B1000: =IF($E1000="","",INDEX('Input Transaksi'!$D:$D,$E1000)) | C1000: =IF($E1000="","",INDEX('Input Transaksi'!$E:$E,$E1000)) | D1000: =IF($E1000="","",INDEX('Input Transaksi'!$F:$F,$E1000)) | E1000: =IFERROR(AGGREGATE(15,6,ROW('Input Transaksi'!$B$5:$B$5000)/('Input Transaksi'!$B$5:$B$5000="BALI WASH GALANG"),ROWS($E$5:E1000)),"")

Sheet JCL BYPASS
A1: JCL BYPASS | F1: Kembali ke Beranda
A2: Wilayah | B2: SELATAN | C2: Total Qty | D2: =SUMIFS('Input Transaksi'!$E$5:$E$5000,'Input Transaksi'!$B$5:$B$5000,"JCL BYPASS") | E2: Jumlah Transaksi | F2: =COUNTIF('Input Transaksi'!$B$5:$B$5000,"JCL BYPASS")
A4: Tanggal | B4: Item | C4: Qty Keluar | D4: Catatan | E4: RowRef
A5: =IF($E5="","",INDEX('Input Transaksi'!$A:$A,$E5)) | B5: =IF($E5="","",INDEX('Input Transaksi'!$D:$D,$E5)) | C5: =IF($E5="","",INDEX('Input Transaksi'!$E:$E,$E5)) | D5: =IF($E5="","",INDEX('Input Transaksi'!$F:$F,$E5)) | E5: =IFERROR(AGGREGATE(15,6,ROW('Input Transaksi'!$B$5:$B$5000)/('Input Transaksi'!$B$5:$B$5000="JCL BYPASS"),ROWS($E$5:E5)),"")
A6: =IF($E6="","",INDEX('Input Transaksi'!$A:$A,$E6)) | B6: =IF($E6="","",INDEX('Input Transaksi'!$D:$D,$E6)) | C6: =IF($E6="","",INDEX('Input Transaksi'!$E:$E,$E6)) | D6: =IF($E6="","",INDEX('Input Transaksi'!$F:$F,$E6)) | E6: =IFERROR(AGGREGATE(15,6,ROW('Input Transaksi'!$B$5:$B$5000)/('Input Transaksi'!$B$5:$B$5000="JCL BYPASS"),ROWS($E$5:E6)),"")
A7: =IF($E7="","",INDEX('Input Transaksi'!$A:$A,$E7)) | B7: =IF($E7="","",INDEX('Input Transaksi'!$D:$D,$E7)) | C7: =IF($E7="","",INDEX('Input Transaksi'!$E:$E,$E7)) | D7: =IF($E7="","",INDEX('Input Transaksi'!$F:$F,$E7)) | E7: =IFERROR(AGGREGATE(15,6,ROW('Input Transaksi'!$B$5:$B$5000)/('Input Transaksi'!$B$5:$B$5000="JCL BYPASS"),ROWS($E$5:E7)),"")
A8: =IF($E8="","",INDEX('Input Transaksi'!$A:$A,$E8)) | B8: =IF($E8="","",INDEX('Input Transaksi'!$D:$D,$E8)) | C8: =IF($E8="","",INDEX('Input Transaksi'!$E:$E,$E8)) | D8: =IF($E8="","",INDEX('Input Transaksi'!$F:$F,$E8)) | E8: =IFERROR(AGGREGATE(15,6,ROW('Input Transaksi'!$B$5:$B$5000)/('Input Transaksi'!$B$5:$B$5000="JCL BYPASS"),ROWS($E$5:E8)),"")
A9: =IF($E9="","",INDEX('Input Transaksi'!$A:$A,$E9)) | B9: =IF($E9="","",INDEX('Input Transaksi'!$D:$D,$E9)) | C9: =IF($E9="","",INDEX('Input Transaksi'!$E:$E,$E9)) | D9: =IF($E9="","",INDEX('Input Transaksi'!$F:$F,$E9)) | E9: =IFERROR(AGGREGATE(15,6,ROW('Input Transaksi'!$B$5:$B$5000)/('Input Transaksi'!$B$5:$B$5000="JCL BYPASS"),ROWS($E$5:E9)),"")
A10: =IF($E10="","",INDEX('Input Transaksi'!$A:$A,$E10)) | B10: =IF($E10="","",INDEX('Input Transaksi'!$D:$D,$E10)) | C10: =IF($E10="","",INDEX('Input Transaksi'!$E:$E,$E10)) | D10: =IF($E10="","",INDEX('Input Transaksi'!$F:$F,$E10)) | E10: =IFERROR(AGGREGATE(15,6,ROW('Input Transaksi'!$B$5:$B$5000)/('Input Transaksi'!$B$5:$B$5000="JCL BYPASS"),ROWS($E$5:E10)),"")
A11: =IF($E11="","",INDEX('Input Transaksi'!$A:$A,$E11)) | B11: =IF($E11="","",INDEX('Input Transaksi'!$D:$D,$E11)) | C11: =IF($E11="","",INDEX('Input Transaksi'!$E:$E,$E11)) | D11: =IF($E11="","",INDEX('Input Transaksi'!$F:$F,$E11)) | E11: =IFERROR(AGGREGATE(15,6,ROW('Input Transaksi'!$B$5:$B$5000)/('Input Transaksi'!$B$5:$B$5000="JCL BYPASS"),ROWS($E$5:E11)),"")
A12: =IF($E12="","",INDEX('Input Transaksi'!$A:$A,$E12)) | B12: =IF($E12="","",INDEX('Input Transaksi'!$D:$D,$E12)) | C12: =IF($E12="","",INDEX('Input Transaksi'!$E:$E,$E12)) | D12: =IF($E12="","",INDEX('Input Transaksi'!$F:$F,$E12)) | E12: =IFERROR(AGGREGATE(15,6,ROW('Input Transaksi'!$B$5:$B$5000)/('Input Transaksi'!$B$5:$B$5000="JCL BYPASS"),ROWS($E$5:E12)),"")
A13: =IF($E13="","",INDEX('Input Transaksi'!$A:$A,$E13)) | B13: =IF($E13="","",INDEX('Input Transaksi'!$D:$D,$E13)) | C13: =IF($E13="","",INDEX('Input Transaksi'!$E:$E,$E13)) | D13: =IF($E13="","",INDEX('Input Transaksi'!$F:$F,$E13)) | E13: =IFERROR(AGGREGATE(15,6,ROW('Input Transaksi'!$B$5:$B$5000)/('Input Transaksi'!$B$5:$B$5000="JCL BYPASS"),ROWS($E$5:E13)),"")
A14: =IF($E14="","",INDEX('Input Transaksi'!$A:$A,$E14)) | B14: =IF($E14="","",INDEX('Input Transaksi'!$D:$D,$E14)) | C14: =IF($E14="","",INDEX('Input Transaksi'!$E:$E,$E14)) | D14: =IF($E14="","",INDEX('Input Transaksi'!$F:$F,$E14)) | E14: =IFERROR(AGGREGATE(15,6,ROW('Input Transaksi'!$B$5:$B$5000)/('Input Transaksi'!$B$5:$B$5000="JCL BYPASS"),ROWS($E$5:E14)),"")
A15: =IF($E15="","",INDEX('Input Transaksi'!$A:$A,$E15)) | B15: =IF($E15="","",INDEX('Input Transaksi'!$D:$D,$E15)) | C15: =IF($E15="","",INDEX('Input Transaksi'!$E:$E,$E15)) | D15: =IF($E15="","",INDEX('Input Transaksi'!$F:$F,$E15)) | E15: =IFERROR(AGGREGATE(15,6,ROW('Input Transaksi'!$B$5:$B$5000)/('Input Transaksi'!$B$5:$B$5000="JCL BYPASS"),ROWS($E$5:E15)),"")
A16: =IF($E16="","",INDEX('Input Transaksi'!$A:$A,$E16)) | B16: =IF($E16="","",INDEX('Input Transaksi'!$D:$D,$E16)) | C16: =IF($E16="","",INDEX('Input Transaksi'!$E:$E,$E16)) | D16: =IF($E16="","",INDEX('Input Transaksi'!$F:$F,$E16)) | E16: =IFERROR(AGGREGATE(15,6,ROW('Input Transaksi'!$B$5:$B$5000)/('Input Transaksi'!$B$5:$B$5000="JCL BYPASS"),ROWS($E$5:E16)),"")
... A1000: =IF($E1000="","",INDEX('Input Transaksi'!$A:$A,$E1000)) | B1000: =IF($E1000="","",INDEX('Input Transaksi'!$D:$D,$E1000)) | C1000: =IF($E1000="","",INDEX('Input Transaksi'!$E:$E,$E1000)) | D1000: =IF($E1000="","",INDEX('Input Transaksi'!$F:$F,$E1000)) | E1000: =IFERROR(AGGREGATE(15,6,ROW('Input Transaksi'!$B$5:$B$5000)/('Input Transaksi'!$B$5:$B$5000="JCL BYPASS"),ROWS($E$5:E1000)),"")

Sheet JCL SESETAN
A1: JCL SESETAN | F1: Kembali ke Beranda
A2: Wilayah | B2: SELATAN | C2: Total Qty | D2: =SUMIFS('Input Transaksi'!$E$5:$E$5000,'Input Transaksi'!$B$5:$B$5000,"JCL SESETAN") | E2: Jumlah Transaksi | F2: =COUNTIF('Input Transaksi'!$B$5:$B$5000,"JCL SESETAN")
A4: Tanggal | B4: Item | C4: Qty Keluar | D4: Catatan | E4: RowRef
A5: =IF($E5="","",INDEX('Input Transaksi'!$A:$A,$E5)) | B5: =IF($E5="","",INDEX('Input Transaksi'!$D:$D,$E5)) | C5: =IF($E5="","",INDEX('Input Transaksi'!$E:$E,$E5)) | D5: =IF($E5="","",INDEX('Input Transaksi'!$F:$F,$E5)) | E5: =IFERROR(AGGREGATE(15,6,ROW('Input Transaksi'!$B$5:$B$5000)/('Input Transaksi'!$B$5:$B$5000="JCL SESETAN"),ROWS($E$5:E5)),"")
A6: =IF($E6="","",INDEX('Input Transaksi'!$A:$A,$E6)) | B6: =IF($E6="","",INDEX('Input Transaksi'!$D:$D,$E6)) | C6: =IF($E6="","",INDEX('Input Transaksi'!$E:$E,$E6)) | D6: =IF($E6="","",INDEX('Input Transaksi'!$F:$F,$E6)) | E6: =IFERROR(AGGREGATE(15,6,ROW('Input Transaksi'!$B$5:$B$5000)/('Input Transaksi'!$B$5:$B$5000="JCL SESETAN"),ROWS($E$5:E6)),"")
A7: =IF($E7="","",INDEX('Input Transaksi'!$A:$A,$E7)) | B7: =IF($E7="","",INDEX('Input Transaksi'!$D:$D,$E7)) | C7: =IF($E7="","",INDEX('Input Transaksi'!$E:$E,$E7)) | D7: =IF($E7="","",INDEX('Input Transaksi'!$F:$F,$E7)) | E7: =IFERROR(AGGREGATE(15,6,ROW('Input Transaksi'!$B$5:$B$5000)/('Input Transaksi'!$B$5:$B$5000="JCL SESETAN"),ROWS($E$5:E7)),"")
A8: =IF($E8="","",INDEX('Input Transaksi'!$A:$A,$E8)) | B8: =IF($E8="","",INDEX('Input Transaksi'!$D:$D,$E8)) | C8: =IF($E8="","",INDEX('Input Transaksi'!$E:$E,$E8)) | D8: =IF($E8="","",INDEX('Input Transaksi'!$F:$F,$E8)) | E8: =IFERROR(AGGREGATE(15,6,ROW('Input Transaksi'!$B$5:$B$5000)/('Input Transaksi'!$B$5:$B$5000="JCL SESETAN"),ROWS($E$5:E8)),"")
A9: =IF($E9="","",INDEX('Input Transaksi'!$A:$A,$E9)) | B9: =IF($E9="","",INDEX('Input Transaksi'!$D:$D,$E9)) | C9: =IF($E9="","",INDEX('Input Transaksi'!$E:$E,$E9)) | D9: =IF($E9="","",INDEX('Input Transaksi'!$F:$F,$E9)) | E9: =IFERROR(AGGREGATE(15,6,ROW('Input Transaksi'!$B$5:$B$5000)/('Input Transaksi'!$B$5:$B$5000="JCL SESETAN"),ROWS($E$5:E9)),"")
A10: =IF($E10="","",INDEX('Input Transaksi'!$A:$A,$E10)) | B10: =IF($E10="","",INDEX('Input Transaksi'!$D:$D,$E10)) | C10: =IF($E10="","",INDEX('Input Transaksi'!$E:$E,$E10)) | D10: =IF($E10="","",INDEX('Input Transaksi'!$F:$F,$E10)) | E10: =IFERROR(AGGREGATE(15,6,ROW('Input Transaksi'!$B$5:$B$5000)/('Input Transaksi'!$B$5:$B$5000="JCL SESETAN"),ROWS($E$5:E10)),"")
A11: =IF($E11="","",INDEX('Input Transaksi'!$A:$A,$E11)) | B11: =IF($E11="","",INDEX('Input Transaksi'!$D:$D,$E11)) | C11: =IF($E11="","",INDEX('Input Transaksi'!$E:$E,$E11)) | D11: =IF($E11="","",INDEX('Input Transaksi'!$F:$F,$E11)) | E11: =IFERROR(AGGREGATE(15,6,ROW('Input Transaksi'!$B$5:$B$5000)/('Input Transaksi'!$B$5:$B$5000="JCL SESETAN"),ROWS($E$5:E11)),"")
A12: =IF($E12="","",INDEX('Input Transaksi'!$A:$A,$E12)) | B12: =IF($E12="","",INDEX('Input Transaksi'!$D:$D,$E12)) | C12: =IF($E12="","",INDEX('Input Transaksi'!$E:$E,$E12)) | D12: =IF($E12="","",INDEX('Input Transaksi'!$F:$F,$E12)) | E12: =IFERROR(AGGREGATE(15,6,ROW('Input Transaksi'!$B$5:$B$5000)/('Input Transaksi'!$B$5:$B$5000="JCL SESETAN"),ROWS($E$5:E12)),"")
A13: =IF($E13="","",INDEX('Input Transaksi'!$A:$A,$E13)) | B13: =IF($E13="","",INDEX('Input Transaksi'!$D:$D,$E13)) | C13: =IF($E13="","",INDEX('Input Transaksi'!$E:$E,$E13)) | D13: =IF($E13="","",INDEX('Input Transaksi'!$F:$F,$E13)) | E13: =IFERROR(AGGREGATE(15,6,ROW('Input Transaksi'!$B$5:$B$5000)/('Input Transaksi'!$B$5:$B$5000="JCL SESETAN"),ROWS($E$5:E13)),"")
A14: =IF($E14="","",INDEX('Input Transaksi'!$A:$A,$E14)) | B14: =IF($E14="","",INDEX('Input Transaksi'!$D:$D,$E14)) | C14: =IF($E14="","",INDEX('Input Transaksi'!$E:$E,$E14)) | D14: =IF($E14="","",INDEX('Input Transaksi'!$F:$F,$E14)) | E14: =IFERROR(AGGREGATE(15,6,ROW('Input Transaksi'!$B$5:$B$5000)/('Input Transaksi'!$B$5:$B$5000="JCL SESETAN"),ROWS($E$5:E14)),"")
A15: =IF($E15="","",INDEX('Input Transaksi'!$A:$A,$E15)) | B15: =IF($E15="","",INDEX('Input Transaksi'!$D:$D,$E15)) | C15: =IF($E15="","",INDEX('Input Transaksi'!$E:$E,$E15)) | D15: =IF($E15="","",INDEX('Input Transaksi'!$F:$F,$E15)) | E15: =IFERROR(AGGREGATE(15,6,ROW('Input Transaksi'!$B$5:$B$5000)/('Input Transaksi'!$B$5:$B$5000="JCL SESETAN"),ROWS($E$5:E15)),"")
A16: =IF($E16="","",INDEX('Input Transaksi'!$A:$A,$E16)) | B16: =IF($E16="","",INDEX('Input Transaksi'!$D:$D,$E16)) | C16: =IF($E16="","",INDEX('Input Transaksi'!$E:$E,$E16)) | D16: =IF($E16="","",INDEX('Input Transaksi'!$F:$F,$E16)) | E16: =IFERROR(AGGREGATE(15,6,ROW('Input Transaksi'!$B$5:$B$5000)/('Input Transaksi'!$B$5:$B$5000="JCL SESETAN"),ROWS($E$5:E16)),"")
... A1000: =IF($E1000="","",INDEX('Input Transaksi'!$A:$A,$E1000)) | B1000: =IF($E1000="","",INDEX('Input Transaksi'!$D:$D,$E1000)) | C1000: =IF($E1000="","",INDEX('Input Transaksi'!$E:$E,$E1000)) | D1000: =IF($E1000="","",INDEX('Input Transaksi'!$F:$F,$E1000)) | E1000: =IFERROR(AGGREGATE(15,6,ROW('Input Transaksi'!$B$5:$B$5000)/('Input Transaksi'!$B$5:$B$5000="JCL SESETAN"),ROWS($E$5:E1000)),"")

Sheet CL SESETAN
A1: CL SESETAN | F1: Kembali ke Beranda
A2: Wilayah | B2: SELATAN | C2: Total Qty | D2: =SUMIFS('Input Transaksi'!$E$5:$E$5000,'Input Transaksi'!$B$5:$B$5000,"CL SESETAN") | E2: Jumlah Transaksi | F2: =COUNTIF('Input Transaksi'!$B$5:$B$5000,"CL SESETAN")
A4: Tanggal | B4: Item | C4: Qty Keluar | D4: Catatan | E4: RowRef
A5: =IF($E5="","",INDEX('Input Transaksi'!$A:$A,$E5)) | B5: =IF($E5="","",INDEX('Input Transaksi'!$D:$D,$E5)) | C5: =IF($E5="","",INDEX('Input Transaksi'!$E:$E,$E5)) | D5: =IF($E5="","",INDEX('Input Transaksi'!$F:$F,$E5)) | E5: =IFERROR(AGGREGATE(15,6,ROW('Input Transaksi'!$B$5:$B$5000)/('Input Transaksi'!$B$5:$B$5000="CL SESETAN"),ROWS($E$5:E5)),"")
A6: =IF($E6="","",INDEX('Input Transaksi'!$A:$A,$E6)) | B6: =IF($E6="","",INDEX('Input Transaksi'!$D:$D,$E6)) | C6: =IF($E6="","",INDEX('Input Transaksi'!$E:$E,$E6)) | D6: =IF($E6="","",INDEX('Input Transaksi'!$F:$F,$E6)) | E6: =IFERROR(AGGREGATE(15,6,ROW('Input Transaksi'!$B$5:$B$5000)/('Input Transaksi'!$B$5:$B$5000="CL SESETAN"),ROWS($E$5:E6)),"")
A7: =IF($E7="","",INDEX('Input Transaksi'!$A:$A,$E7)) | B7: =IF($E7="","",INDEX('Input Transaksi'!$D:$D,$E7)) | C7: =IF($E7="","",INDEX('Input Transaksi'!$E:$E,$E7)) | D7: =IF($E7="","",INDEX('Input Transaksi'!$F:$F,$E7)) | E7: =IFERROR(AGGREGATE(15,6,ROW('Input Transaksi'!$B$5:$B$5000)/('Input Transaksi'!$B$5:$B$5000="CL SESETAN"),ROWS($E$5:E7)),"")
A8: =IF($E8="","",INDEX('Input Transaksi'!$A:$A,$E8)) | B8: =IF($E8="","",INDEX('Input Transaksi'!$D:$D,$E8)) | C8: =IF($E8="","",INDEX('Input Transaksi'!$E:$E,$E8)) | D8: =IF($E8="","",INDEX('Input Transaksi'!$F:$F,$E8)) | E8: =IFERROR(AGGREGATE(15,6,ROW('Input Transaksi'!$B$5:$B$5000)/('Input Transaksi'!$B$5:$B$5000="CL SESETAN"),ROWS($E$5:E8)),"")
A9: =IF($E9="","",INDEX('Input Transaksi'!$A:$A,$E9)) | B9: =IF($E9="","",INDEX('Input Transaksi'!$D:$D,$E9)) | C9: =IF($E9="","",INDEX('Input Transaksi'!$E:$E,$E9)) | D9: =IF($E9="","",INDEX('Input Transaksi'!$F:$F,$E9)) | E9: =IFERROR(AGGREGATE(15,6,ROW('Input Transaksi'!$B$5:$B$5000)/('Input Transaksi'!$B$5:$B$5000="CL SESETAN"),ROWS($E$5:E9)),"")
A10: =IF($E10="","",INDEX('Input Transaksi'!$A:$A,$E10)) | B10: =IF($E10="","",INDEX('Input Transaksi'!$D:$D,$E10)) | C10: =IF($E10="","",INDEX('Input Transaksi'!$E:$E,$E10)) | D10: =IF($E10="","",INDEX('Input Transaksi'!$F:$F,$E10)) | E10: =IFERROR(AGGREGATE(15,6,ROW('Input Transaksi'!$B$5:$B$5000)/('Input Transaksi'!$B$5:$B$5000="CL SESETAN"),ROWS($E$5:E10)),"")
A11: =IF($E11="","",INDEX('Input Transaksi'!$A:$A,$E11)) | B11: =IF($E11="","",INDEX('Input Transaksi'!$D:$D,$E11)) | C11: =IF($E11="","",INDEX('Input Transaksi'!$E:$E,$E11)) | D11: =IF($E11="","",INDEX('Input Transaksi'!$F:$F,$E11)) | E11: =IFERROR(AGGREGATE(15,6,ROW('Input Transaksi'!$B$5:$B$5000)/('Input Transaksi'!$B$5:$B$5000="CL SESETAN"),ROWS($E$5:E11)),"")
A12: =IF($E12="","",INDEX('Input Transaksi'!$A:$A,$E12)) | B12: =IF($E12="","",INDEX('Input Transaksi'!$D:$D,$E12)) | C12: =IF($E12="","",INDEX('Input Transaksi'!$E:$E,$E12)) | D12: =IF($E12="","",INDEX('Input Transaksi'!$F:$F,$E12)) | E12: =IFERROR(AGGREGATE(15,6,ROW('Input Transaksi'!$B$5:$B$5000)/('Input Transaksi'!$B$5:$B$5000="CL SESETAN"),ROWS($E$5:E12)),"")
A13: =IF($E13="","",INDEX('Input Transaksi'!$A:$A,$E13)) | B13: =IF($E13="","",INDEX('Input Transaksi'!$D:$D,$E13)) | C13: =IF($E13="","",INDEX('Input Transaksi'!$E:$E,$E13)) | D13: =IF($E13="","",INDEX('Input Transaksi'!$F:$F,$E13)) | E13: =IFERROR(AGGREGATE(15,6,ROW('Input Transaksi'!$B$5:$B$5000)/('Input Transaksi'!$B$5:$B$5000="CL SESETAN"),ROWS($E$5:E13)),"")
A14: =IF($E14="","",INDEX('Input Transaksi'!$A:$A,$E14)) | B14: =IF($E14="","",INDEX('Input Transaksi'!$D:$D,$E14)) | C14: =IF($E14="","",INDEX('Input Transaksi'!$E:$E,$E14)) | D14: =IF($E14="","",INDEX('Input Transaksi'!$F:$F,$E14)) | E14: =IFERROR(AGGREGATE(15,6,ROW('Input Transaksi'!$B$5:$B$5000)/('Input Transaksi'!$B$5:$B$5000="CL SESETAN"),ROWS($E$5:E14)),"")
A15: =IF($E15="","",INDEX('Input Transaksi'!$A:$A,$E15)) | B15: =IF($E15="","",INDEX('Input Transaksi'!$D:$D,$E15)) | C15: =IF($E15="","",INDEX('Input Transaksi'!$E:$E,$E15)) | D15: =IF($E15="","",INDEX('Input Transaksi'!$F:$F,$E15)) | E15: =IFERROR(AGGREGATE(15,6,ROW('Input Transaksi'!$B$5:$B$5000)/('Input Transaksi'!$B$5:$B$5000="CL SESETAN"),ROWS($E$5:E15)),"")
A16: =IF($E16="","",INDEX('Input Transaksi'!$A:$A,$E16)) | B16: =IF($E16="","",INDEX('Input Transaksi'!$D:$D,$E16)) | C16: =IF($E16="","",INDEX('Input Transaksi'!$E:$E,$E16)) | D16: =IF($E16="","",INDEX('Input Transaksi'!$F:$F,$E16)) | E16: =IFERROR(AGGREGATE(15,6,ROW('Input Transaksi'!$B$5:$B$5000)/('Input Transaksi'!$B$5:$B$5000="CL SESETAN"),ROWS($E$5:E16)),"")
... A1000: =IF($E1000="","",INDEX('Input Transaksi'!$A:$A,$E1000)) | B1000: =IF($E1000="","",INDEX('Input Transaksi'!$D:$D,$E1000)) | C1000: =IF($E1000="","",INDEX('Input Transaksi'!$E:$E,$E1000)) | D1000: =IF($E1000="","",INDEX('Input Transaksi'!$F:$F,$E1000)) | E1000: =IFERROR(AGGREGATE(15,6,ROW('Input Transaksi'!$B$5:$B$5000)/('Input Transaksi'!$B$5:$B$5000="CL SESETAN"),ROWS($E$5:E1000)),"")

Sheet GRIYA ANYAR
A1: GRIYA ANYAR | F1: Kembali ke Beranda
A2: Wilayah | B2: SELATAN | C2: Total Qty | D2: =SUMIFS('Input Transaksi'!$E$5:$E$5000,'Input Transaksi'!$B$5:$B$5000,"GRIYA ANYAR") | E2: Jumlah Transaksi | F2: =COUNTIF('Input Transaksi'!$B$5:$B$5000,"GRIYA ANYAR")
A4: Tanggal | B4: Item | C4: Qty Keluar | D4: Catatan | E4: RowRef
A5: =IF($E5="","",INDEX('Input Transaksi'!$A:$A,$E5)) | B5: =IF($E5="","",INDEX('Input Transaksi'!$D:$D,$E5)) | C5: =IF($E5="","",INDEX('Input Transaksi'!$E:$E,$E5)) | D5: =IF($E5="","",INDEX('Input Transaksi'!$F:$F,$E5)) | E5: =IFERROR(AGGREGATE(15,6,ROW('Input Transaksi'!$B$5:$B$5000)/('Input Transaksi'!$B$5:$B$5000="GRIYA ANYAR"),ROWS($E$5:E5)),"")
A6: =IF($E6="","",INDEX('Input Transaksi'!$A:$A,$E6)) | B6: =IF($E6="","",INDEX('Input Transaksi'!$D:$D,$E6)) | C6: =IF($E6="","",INDEX('Input Transaksi'!$E:$E,$E6)) | D6: =IF($E6="","",INDEX('Input Transaksi'!$F:$F,$E6)) | E6: =IFERROR(AGGREGATE(15,6,ROW('Input Transaksi'!$B$5:$B$5000)/('Input Transaksi'!$B$5:$B$5000="GRIYA ANYAR"),ROWS($E$5:E6)),"")
A7: =IF($E7="","",INDEX('Input Transaksi'!$A:$A,$E7)) | B7: =IF($E7="","",INDEX('Input Transaksi'!$D:$D,$E7)) | C7: =IF($E7="","",INDEX('Input Transaksi'!$E:$E,$E7)) | D7: =IF($E7="","",INDEX('Input Transaksi'!$F:$F,$E7)) | E7: =IFERROR(AGGREGATE(15,6,ROW('Input Transaksi'!$B$5:$B$5000)/('Input Transaksi'!$B$5:$B$5000="GRIYA ANYAR"),ROWS($E$5:E7)),"")
A8: =IF($E8="","",INDEX('Input Transaksi'!$A:$A,$E8)) | B8: =IF($E8="","",INDEX('Input Transaksi'!$D:$D,$E8)) | C8: =IF($E8="","",INDEX('Input Transaksi'!$E:$E,$E8)) | D8: =IF($E8="","",INDEX('Input Transaksi'!$F:$F,$E8)) | E8: =IFERROR(AGGREGATE(15,6,ROW('Input Transaksi'!$B$5:$B$5000)/('Input Transaksi'!$B$5:$B$5000="GRIYA ANYAR"),ROWS($E$5:E8)),"")
A9: =IF($E9="","",INDEX('Input Transaksi'!$A:$A,$E9)) | B9: =IF($E9="","",INDEX('Input Transaksi'!$D:$D,$E9)) | C9: =IF($E9="","",INDEX('Input Transaksi'!$E:$E,$E9)) | D9: =IF($E9="","",INDEX('Input Transaksi'!$F:$F,$E9)) | E9: =IFERROR(AGGREGATE(15,6,ROW('Input Transaksi'!$B$5:$B$5000)/('Input Transaksi'!$B$5:$B$5000="GRIYA ANYAR"),ROWS($E$5:E9)),"")
A10: =IF($E10="","",INDEX('Input Transaksi'!$A:$A,$E10)) | B10: =IF($E10="","",INDEX('Input Transaksi'!$D:$D,$E10)) | C10: =IF($E10="","",INDEX('Input Transaksi'!$E:$E,$E10)) | D10: =IF($E10="","",INDEX('Input Transaksi'!$F:$F,$E10)) | E10: =IFERROR(AGGREGATE(15,6,ROW('Input Transaksi'!$B$5:$B$5000)/('Input Transaksi'!$B$5:$B$5000="GRIYA ANYAR"),ROWS($E$5:E10)),"")
A11: =IF($E11="","",INDEX('Input Transaksi'!$A:$A,$E11)) | B11: =IF($E11="","",INDEX('Input Transaksi'!$D:$D,$E11)) | C11: =IF($E11="","",INDEX('Input Transaksi'!$E:$E,$E11)) | D11: =IF($E11="","",INDEX('Input Transaksi'!$F:$F,$E11)) | E11: =IFERROR(AGGREGATE(15,6,ROW('Input Transaksi'!$B$5:$B$5000)/('Input Transaksi'!$B$5:$B$5000="GRIYA ANYAR"),ROWS($E$5:E11)),"")
A12: =IF($E12="","",INDEX('Input Transaksi'!$A:$A,$E12)) | B12: =IF($E12="","",INDEX('Input Transaksi'!$D:$D,$E12)) | C12: =IF($E12="","",INDEX('Input Transaksi'!$E:$E,$E12)) | D12: =IF($E12="","",INDEX('Input Transaksi'!$F:$F,$E12)) | E12: =IFERROR(AGGREGATE(15,6,ROW('Input Transaksi'!$B$5:$B$5000)/('Input Transaksi'!$B$5:$B$5000="GRIYA ANYAR"),ROWS($E$5:E12)),"")
A13: =IF($E13="","",INDEX('Input Transaksi'!$A:$A,$E13)) | B13: =IF($E13="","",INDEX('Input Transaksi'!$D:$D,$E13)) | C13: =IF($E13="","",INDEX('Input Transaksi'!$E:$E,$E13)) | D13: =IF($E13="","",INDEX('Input Transaksi'!$F:$F,$E13)) | E13: =IFERROR(AGGREGATE(15,6,ROW('Input Transaksi'!$B$5:$B$5000)/('Input Transaksi'!$B$5:$B$5000="GRIYA ANYAR"),ROWS($E$5:E13)),"")
A14: =IF($E14="","",INDEX('Input Transaksi'!$A:$A,$E14)) | B14: =IF($E14="","",INDEX('Input Transaksi'!$D:$D,$E14)) | C14: =IF($E14="","",INDEX('Input Transaksi'!$E:$E,$E14)) | D14: =IF($E14="","",INDEX('Input Transaksi'!$F:$F,$E14)) | E14: =IFERROR(AGGREGATE(15,6,ROW('Input Transaksi'!$B$5:$B$5000)/('Input Transaksi'!$B$5:$B$5000="GRIYA ANYAR"),ROWS($E$5:E14)),"")
A15: =IF($E15="","",INDEX('Input Transaksi'!$A:$A,$E15)) | B15: =IF($E15="","",INDEX('Input Transaksi'!$D:$D,$E15)) | C15: =IF($E15="","",INDEX('Input Transaksi'!$E:$E,$E15)) | D15: =IF($E15="","",INDEX('Input Transaksi'!$F:$F,$E15)) | E15: =IFERROR(AGGREGATE(15,6,ROW('Input Transaksi'!$B$5:$B$5000)/('Input Transaksi'!$B$5:$B$5000="GRIYA ANYAR"),ROWS($E$5:E15)),"")
A16: =IF($E16="","",INDEX('Input Transaksi'!$A:$A,$E16)) | B16: =IF($E16="","",INDEX('Input Transaksi'!$D:$D,$E16)) | C16: =IF($E16="","",INDEX('Input Transaksi'!$E:$E,$E16)) | D16: =IF($E16="","",INDEX('Input Transaksi'!$F:$F,$E16)) | E16: =IFERROR(AGGREGATE(15,6,ROW('Input Transaksi'!$B$5:$B$5000)/('Input Transaksi'!$B$5:$B$5000="GRIYA ANYAR"),ROWS($E$5:E16)),"")
... A1000: =IF($E1000="","",INDEX('Input Transaksi'!$A:$A,$E1000)) | B1000: =IF($E1000="","",INDEX('Input Transaksi'!$D:$D,$E1000)) | C1000: =IF($E1000="","",INDEX('Input Transaksi'!$E:$E,$E1000)) | D1000: =IF($E1000="","",INDEX('Input Transaksi'!$F:$F,$E1000)) | E1000: =IFERROR(AGGREGATE(15,6,ROW('Input Transaksi'!$B$5:$B$5000)/('Input Transaksi'!$B$5:$B$5000="GRIYA ANYAR"),ROWS($E$5:E1000)),"")

Sheet KLIN WASH
A1: KLIN WASH | F1: Kembali ke Beranda
A2: Wilayah | B2: SELATAN | C2: Total Qty | D2: =SUMIFS('Input Transaksi'!$E$5:$E$5000,'Input Transaksi'!$B$5:$B$5000,"KLIN WASH") | E2: Jumlah Transaksi | F2: =COUNTIF('Input Transaksi'!$B$5:$B$5000,"KLIN WASH")
A4: Tanggal | B4: Item | C4: Qty Keluar | D4: Catatan | E4: RowRef
A5: =IF($E5="","",INDEX('Input Transaksi'!$A:$A,$E5)) | B5: =IF($E5="","",INDEX('Input Transaksi'!$D:$D,$E5)) | C5: =IF($E5="","",INDEX('Input Transaksi'!$E:$E,$E5)) | D5: =IF($E5="","",INDEX('Input Transaksi'!$F:$F,$E5)) | E5: =IFERROR(AGGREGATE(15,6,ROW('Input Transaksi'!$B$5:$B$5000)/('Input Transaksi'!$B$5:$B$5000="KLIN WASH"),ROWS($E$5:E5)),"")
A6: =IF($E6="","",INDEX('Input Transaksi'!$A:$A,$E6)) | B6: =IF($E6="","",INDEX('Input Transaksi'!$D:$D,$E6)) | C6: =IF($E6="","",INDEX('Input Transaksi'!$E:$E,$E6)) | D6: =IF($E6="","",INDEX('Input Transaksi'!$F:$F,$E6)) | E6: =IFERROR(AGGREGATE(15,6,ROW('Input Transaksi'!$B$5:$B$5000)/('Input Transaksi'!$B$5:$B$5000="KLIN WASH"),ROWS($E$5:E6)),"")
A7: =IF($E7="","",INDEX('Input Transaksi'!$A:$A,$E7)) | B7: =IF($E7="","",INDEX('Input Transaksi'!$D:$D,$E7)) | C7: =IF($E7="","",INDEX('Input Transaksi'!$E:$E,$E7)) | D7: =IF($E7="","",INDEX('Input Transaksi'!$F:$F,$E7)) | E7: =IFERROR(AGGREGATE(15,6,ROW('Input Transaksi'!$B$5:$B$5000)/('Input Transaksi'!$B$5:$B$5000="KLIN WASH"),ROWS($E$5:E7)),"")
A8: =IF($E8="","",INDEX('Input Transaksi'!$A:$A,$E8)) | B8: =IF($E8="","",INDEX('Input Transaksi'!$D:$D,$E8)) | C8: =IF($E8="","",INDEX('Input Transaksi'!$E:$E,$E8)) | D8: =IF($E8="","",INDEX('Input Transaksi'!$F:$F,$E8)) | E8: =IFERROR(AGGREGATE(15,6,ROW('Input Transaksi'!$B$5:$B$5000)/('Input Transaksi'!$B$5:$B$5000="KLIN WASH"),ROWS($E$5:E8)),"")
A9: =IF($E9="","",INDEX('Input Transaksi'!$A:$A,$E9)) | B9: =IF($E9="","",INDEX('Input Transaksi'!$D:$D,$E9)) | C9: =IF($E9="","",INDEX('Input Transaksi'!$E:$E,$E9)) | D9: =IF($E9="","",INDEX('Input Transaksi'!$F:$F,$E9)) | E9: =IFERROR(AGGREGATE(15,6,ROW('Input Transaksi'!$B$5:$B$5000)/('Input Transaksi'!$B$5:$B$5000="KLIN WASH"),ROWS($E$5:E9)),"")
A10: =IF($E10="","",INDEX('Input Transaksi'!$A:$A,$E10)) | B10: =IF($E10="","",INDEX('Input Transaksi'!$D:$D,$E10)) | C10: =IF($E10="","",INDEX('Input Transaksi'!$E:$E,$E10)) | D10: =IF($E10="","",INDEX('Input Transaksi'!$F:$F,$E10)) | E10: =IFERROR(AGGREGATE(15,6,ROW('Input Transaksi'!$B$5:$B$5000)/('Input Transaksi'!$B$5:$B$5000="KLIN WASH"),ROWS($E$5:E10)),"")
A11: =IF($E11="","",INDEX('Input Transaksi'!$A:$A,$E11)) | B11: =IF($E11="","",INDEX('Input Transaksi'!$D:$D,$E11)) | C11: =IF($E11="","",INDEX('Input Transaksi'!$E:$E,$E11)) | D11: =IF($E11="","",INDEX('Input Transaksi'!$F:$F,$E11)) | E11: =IFERROR(AGGREGATE(15,6,ROW('Input Transaksi'!$B$5:$B$5000)/('Input Transaksi'!$B$5:$B$5000="KLIN WASH"),ROWS($E$5:E11)),"")
A12: =IF($E12="","",INDEX('Input Transaksi'!$A:$A,$E12)) | B12: =IF($E12="","",INDEX('Input Transaksi'!$D:$D,$E12)) | C12: =IF($E12="","",INDEX('Input Transaksi'!$E:$E,$E12)) | D12: =IF($E12="","",INDEX('Input Transaksi'!$F:$F,$E12)) | E12: =IFERROR(AGGREGATE(15,6,ROW('Input Transaksi'!$B$5:$B$5000)/('Input Transaksi'!$B$5:$B$5000="KLIN WASH"),ROWS($E$5:E12)),"")
A13: =IF($E13="","",INDEX('Input Transaksi'!$A:$A,$E13)) | B13: =IF($E13="","",INDEX('Input Transaksi'!$D:$D,$E13)) | C13: =IF($E13="","",INDEX('Input Transaksi'!$E:$E,$E13)) | D13: =IF($E13="","",INDEX('Input Transaksi'!$F:$F,$E13)) | E13: =IFERROR(AGGREGATE(15,6,ROW('Input Transaksi'!$B$5:$B$5000)/('Input Transaksi'!$B$5:$B$5000="KLIN WASH"),ROWS($E$5:E13)),"")
A14: =IF($E14="","",INDEX('Input Transaksi'!$A:$A,$E14)) | B14: =IF($E14="","",INDEX('Input Transaksi'!$D:$D,$E14)) | C14: =IF($E14="","",INDEX('Input Transaksi'!$E:$E,$E14)) | D14: =IF($E14="","",INDEX('Input Transaksi'!$F:$F,$E14)) | E14: =IFERROR(AGGREGATE(15,6,ROW('Input Transaksi'!$B$5:$B$5000)/('Input Transaksi'!$B$5:$B$5000="KLIN WASH"),ROWS($E$5:E14)),"")
A15: =IF($E15="","",INDEX('Input Transaksi'!$A:$A,$E15)) | B15: =IF($E15="","",INDEX('Input Transaksi'!$D:$D,$E15)) | C15: =IF($E15="","",INDEX('Input Transaksi'!$E:$E,$E15)) | D15: =IF($E15="","",INDEX('Input Transaksi'!$F:$F,$E15)) | E15: =IFERROR(AGGREGATE(15,6,ROW('Input Transaksi'!$B$5:$B$5000)/('Input Transaksi'!$B$5:$B$5000="KLIN WASH"),ROWS($E$5:E15)),"")
A16: =IF($E16="","",INDEX('Input Transaksi'!$A:$A,$E16)) | B16: =IF($E16="","",INDEX('Input Transaksi'!$D:$D,$E16)) | C16: =IF($E16="","",INDEX('Input Transaksi'!$E:$E,$E16)) | D16: =IF($E16="","",INDEX('Input Transaksi'!$F:$F,$E16)) | E16: =IFERROR(AGGREGATE(15,6,ROW('Input Transaksi'!$B$5:$B$5000)/('Input Transaksi'!$B$5:$B$5000="KLIN WASH"),ROWS($E$5:E16)),"")
... A1000: =IF($E1000="","",INDEX('Input Transaksi'!$A:$A,$E1000)) | B1000: =IF($E1000="","",INDEX('Input Transaksi'!$D:$D,$E1000)) | C1000: =IF($E1000="","",INDEX('Input Transaksi'!$E:$E,$E1000)) | D1000: =IF($E1000="","",INDEX('Input Transaksi'!$F:$F,$E1000)) | E1000: =IFERROR(AGGREGATE(15,6,ROW('Input Transaksi'!$B$5:$B$5000)/('Input Transaksi'!$B$5:$B$5000="KLIN WASH"),ROWS($E$5:E1000)),"")

Sheet LONDRI DEWE
A1: LONDRI DEWE | F1: Kembali ke Beranda
A2: Wilayah | B2: SELATAN | C2: Total Qty | D2: =SUMIFS('Input Transaksi'!$E$5:$E$5000,'Input Transaksi'!$B$5:$B$5000,"LONDRI DEWE") | E2: Jumlah Transaksi | F2: =COUNTIF('Input Transaksi'!$B$5:$B$5000,"LONDRI DEWE")
A4: Tanggal | B4: Item | C4: Qty Keluar | D4: Catatan | E4: RowRef
A5: =IF($E5="","",INDEX('Input Transaksi'!$A:$A,$E5)) | B5: =IF($E5="","",INDEX('Input Transaksi'!$D:$D,$E5)) | C5: =IF($E5="","",INDEX('Input Transaksi'!$E:$E,$E5)) | D5: =IF($E5="","",INDEX('Input Transaksi'!$F:$F,$E5)) | E5: =IFERROR(AGGREGATE(15,6,ROW('Input Transaksi'!$B$5:$B$5000)/('Input Transaksi'!$B$5:$B$5000="LONDRI DEWE"),ROWS($E$5:E5)),"")
A6: =IF($E6="","",INDEX('Input Transaksi'!$A:$A,$E6)) | B6: =IF($E6="","",INDEX('Input Transaksi'!$D:$D,$E6)) | C6: =IF($E6="","",INDEX('Input Transaksi'!$E:$E,$E6)) | D6: =IF($E6="","",INDEX('Input Transaksi'!$F:$F,$E6)) | E6: =IFERROR(AGGREGATE(15,6,ROW('Input Transaksi'!$B$5:$B$5000)/('Input Transaksi'!$B$5:$B$5000="LONDRI DEWE"),ROWS($E$5:E6)),"")
A7: =IF($E7="","",INDEX('Input Transaksi'!$A:$A,$E7)) | B7: =IF($E7="","",INDEX('Input Transaksi'!$D:$D,$E7)) | C7: =IF($E7="","",INDEX('Input Transaksi'!$E:$E,$E7)) | D7: =IF($E7="","",INDEX('Input Transaksi'!$F:$F,$E7)) | E7: =IFERROR(AGGREGATE(15,6,ROW('Input Transaksi'!$B$5:$B$5000)/('Input Transaksi'!$B$5:$B$5000="LONDRI DEWE"),ROWS($E$5:E7)),"")
A8: =IF($E8="","",INDEX('Input Transaksi'!$A:$A,$E8)) | B8: =IF($E8="","",INDEX('Input Transaksi'!$D:$D,$E8)) | C8: =IF($E8="","",INDEX('Input Transaksi'!$E:$E,$E8)) | D8: =IF($E8="","",INDEX('Input Transaksi'!$F:$F,$E8)) | E8: =IFERROR(AGGREGATE(15,6,ROW('Input Transaksi'!$B$5:$B$5000)/('Input Transaksi'!$B$5:$B$5000="LONDRI DEWE"),ROWS($E$5:E8)),"")
A9: =IF($E9="","",INDEX('Input Transaksi'!$A:$A,$E9)) | B9: =IF($E9="","",INDEX('Input Transaksi'!$D:$D,$E9)) | C9: =IF($E9="","",INDEX('Input Transaksi'!$E:$E,$E9)) | D9: =IF($E9="","",INDEX('Input Transaksi'!$F:$F,$E9)) | E9: =IFERROR(AGGREGATE(15,6,ROW('Input Transaksi'!$B$5:$B$5000)/('Input Transaksi'!$B$5:$B$5000="LONDRI DEWE"),ROWS($E$5:E9)),"")
A10: =IF($E10="","",INDEX('Input Transaksi'!$A:$A,$E10)) | B10: =IF($E10="","",INDEX('Input Transaksi'!$D:$D,$E10)) | C10: =IF($E10="","",INDEX('Input Transaksi'!$E:$E,$E10)) | D10: =IF($E10="","",INDEX('Input Transaksi'!$F:$F,$E10)) | E10: =IFERROR(AGGREGATE(15,6,ROW('Input Transaksi'!$B$5:$B$5000)/('Input Transaksi'!$B$5:$B$5000="LONDRI DEWE"),ROWS($E$5:E10)),"")
A11: =IF($E11="","",INDEX('Input Transaksi'!$A:$A,$E11)) | B11: =IF($E11="","",INDEX('Input Transaksi'!$D:$D,$E11)) | C11: =IF($E11="","",INDEX('Input Transaksi'!$E:$E,$E11)) | D11: =IF($E11="","",INDEX('Input Transaksi'!$F:$F,$E11)) | E11: =IFERROR(AGGREGATE(15,6,ROW('Input Transaksi'!$B$5:$B$5000)/('Input Transaksi'!$B$5:$B$5000="LONDRI DEWE"),ROWS($E$5:E11)),"")
A12: =IF($E12="","",INDEX('Input Transaksi'!$A:$A,$E12)) | B12: =IF($E12="","",INDEX('Input Transaksi'!$D:$D,$E12)) | C12: =IF($E12="","",INDEX('Input Transaksi'!$E:$E,$E12)) | D12: =IF($E12="","",INDEX('Input Transaksi'!$F:$F,$E12)) | E12: =IFERROR(AGGREGATE(15,6,ROW('Input Transaksi'!$B$5:$B$5000)/('Input Transaksi'!$B$5:$B$5000="LONDRI DEWE"),ROWS($E$5:E12)),"")
A13: =IF($E13="","",INDEX('Input Transaksi'!$A:$A,$E13)) | B13: =IF($E13="","",INDEX('Input Transaksi'!$D:$D,$E13)) | C13: =IF($E13="","",INDEX('Input Transaksi'!$E:$E,$E13)) | D13: =IF($E13="","",INDEX('Input Transaksi'!$F:$F,$E13)) | E13: =IFERROR(AGGREGATE(15,6,ROW('Input Transaksi'!$B$5:$B$5000)/('Input Transaksi'!$B$5:$B$5000="LONDRI DEWE"),ROWS($E$5:E13)),"")
A14: =IF($E14="","",INDEX('Input Transaksi'!$A:$A,$E14)) | B14: =IF($E14="","",INDEX('Input Transaksi'!$D:$D,$E14)) | C14: =IF($E14="","",INDEX('Input Transaksi'!$E:$E,$E14)) | D14: =IF($E14="","",INDEX('Input Transaksi'!$F:$F,$E14)) | E14: =IFERROR(AGGREGATE(15,6,ROW('Input Transaksi'!$B$5:$B$5000)/('Input Transaksi'!$B$5:$B$5000="LONDRI DEWE"),ROWS($E$5:E14)),"")
A15: =IF($E15="","",INDEX('Input Transaksi'!$A:$A,$E15)) | B15: =IF($E15="","",INDEX('Input Transaksi'!$D:$D,$E15)) | C15: =IF($E15="","",INDEX('Input Transaksi'!$E:$E,$E15)) | D15: =IF($E15="","",INDEX('Input Transaksi'!$F:$F,$E15)) | E15: =IFERROR(AGGREGATE(15,6,ROW('Input Transaksi'!$B$5:$B$5000)/('Input Transaksi'!$B$5:$B$5000="LONDRI DEWE"),ROWS($E$5:E15)),"")
A16: =IF($E16="","",INDEX('Input Transaksi'!$A:$A,$E16)) | B16: =IF($E16="","",INDEX('Input Transaksi'!$D:$D,$E16)) | C16: =IF($E16="","",INDEX('Input Transaksi'!$E:$E,$E16)) | D16: =IF($E16="","",INDEX('Input Transaksi'!$F:$F,$E16)) | E16: =IFERROR(AGGREGATE(15,6,ROW('Input Transaksi'!$B$5:$B$5000)/('Input Transaksi'!$B$5:$B$5000="LONDRI DEWE"),ROWS($E$5:E16)),"")
... A1000: =IF($E1000="","",INDEX('Input Transaksi'!$A:$A,$E1000)) | B1000: =IF($E1000="","",INDEX('Input Transaksi'!$D:$D,$E1000)) | C1000: =IF($E1000="","",INDEX('Input Transaksi'!$E:$E,$E1000)) | D1000: =IF($E1000="","",INDEX('Input Transaksi'!$F:$F,$E1000)) | E1000: =IFERROR(AGGREGATE(15,6,ROW('Input Transaksi'!$B$5:$B$5000)/('Input Transaksi'!$B$5:$B$5000="LONDRI DEWE"),ROWS($E$5:E1000)),"")

Sheet DIY
A1: DIY | F1: Kembali ke Beranda
A2: Wilayah | B2: SELATAN | C2: Total Qty | D2: =SUMIFS('Input Transaksi'!$E$5:$E$5000,'Input Transaksi'!$B$5:$B$5000,"DIY") | E2: Jumlah Transaksi | F2: =COUNTIF('Input Transaksi'!$B$5:$B$5000,"DIY")
A4: Tanggal | B4: Item | C4: Qty Keluar | D4: Catatan | E4: RowRef
A5: =IF($E5="","",INDEX('Input Transaksi'!$A:$A,$E5)) | B5: =IF($E5="","",INDEX('Input Transaksi'!$D:$D,$E5)) | C5: =IF($E5="","",INDEX('Input Transaksi'!$E:$E,$E5)) | D5: =IF($E5="","",INDEX('Input Transaksi'!$F:$F,$E5)) | E5: =IFERROR(AGGREGATE(15,6,ROW('Input Transaksi'!$B$5:$B$5000)/('Input Transaksi'!$B$5:$B$5000="DIY"),ROWS($E$5:E5)),"")
A6: =IF($E6="","",INDEX('Input Transaksi'!$A:$A,$E6)) | B6: =IF($E6="","",INDEX('Input Transaksi'!$D:$D,$E6)) | C6: =IF($E6="","",INDEX('Input Transaksi'!$E:$E,$E6)) | D6: =IF($E6="","",INDEX('Input Transaksi'!$F:$F,$E6)) | E6: =IFERROR(AGGREGATE(15,6,ROW('Input Transaksi'!$B$5:$B$5000)/('Input Transaksi'!$B$5:$B$5000="DIY"),ROWS($E$5:E6)),"")
A7: =IF($E7="","",INDEX('Input Transaksi'!$A:$A,$E7)) | B7: =IF($E7="","",INDEX('Input Transaksi'!$D:$D,$E7)) | C7: =IF($E7="","",INDEX('Input Transaksi'!$E:$E,$E7)) | D7: =IF($E7="","",INDEX('Input Transaksi'!$F:$F,$E7)) | E7: =IFERROR(AGGREGATE(15,6,ROW('Input Transaksi'!$B$5:$B$5000)/('Input Transaksi'!$B$5:$B$5000="DIY"),ROWS($E$5:E7)),"")
A8: =IF($E8="","",INDEX('Input Transaksi'!$A:$A,$E8)) | B8: =IF($E8="","",INDEX('Input Transaksi'!$D:$D,$E8)) | C8: =IF($E8="","",INDEX('Input Transaksi'!$E:$E,$E8)) | D8: =IF($E8="","",INDEX('Input Transaksi'!$F:$F,$E8)) | E8: =IFERROR(AGGREGATE(15,6,ROW('Input Transaksi'!$B$5:$B$5000)/('Input Transaksi'!$B$5:$B$5000="DIY"),ROWS($E$5:E8)),"")
A9: =IF($E9="","",INDEX('Input Transaksi'!$A:$A,$E9)) | B9: =IF($E9="","",INDEX('Input Transaksi'!$D:$D,$E9)) | C9: =IF($E9="","",INDEX('Input Transaksi'!$E:$E,$E9)) | D9: =IF($E9="","",INDEX('Input Transaksi'!$F:$F,$E9)) | E9: =IFERROR(AGGREGATE(15,6,ROW('Input Transaksi'!$B$5:$B$5000)/('Input Transaksi'!$B$5:$B$5000="DIY"),ROWS($E$5:E9)),"")
A10: =IF($E10="","",INDEX('Input Transaksi'!$A:$A,$E10)) | B10: =IF($E10="","",INDEX('Input Transaksi'!$D:$D,$E10)) | C10: =IF($E10="","",INDEX('Input Transaksi'!$E:$E,$E10)) | D10: =IF($E10="","",INDEX('Input Transaksi'!$F:$F,$E10)) | E10: =IFERROR(AGGREGATE(15,6,ROW('Input Transaksi'!$B$5:$B$5000)/('Input Transaksi'!$B$5:$B$5000="DIY"),ROWS($E$5:E10)),"")
A11: =IF($E11="","",INDEX('Input Transaksi'!$A:$A,$E11)) | B11: =IF($E11="","",INDEX('Input Transaksi'!$D:$D,$E11)) | C11: =IF($E11="","",INDEX('Input Transaksi'!$E:$E,$E11)) | D11: =IF($E11="","",INDEX('Input Transaksi'!$F:$F,$E11)) | E11: =IFERROR(AGGREGATE(15,6,ROW('Input Transaksi'!$B$5:$B$5000)/('Input Transaksi'!$B$5:$B$5000="DIY"),ROWS($E$5:E11)),"")
A12: =IF($E12="","",INDEX('Input Transaksi'!$A:$A,$E12)) | B12: =IF($E12="","",INDEX('Input Transaksi'!$D:$D,$E12)) | C12: =IF($E12="","",INDEX('Input Transaksi'!$E:$E,$E12)) | D12: =IF($E12="","",INDEX('Input Transaksi'!$F:$F,$E12)) | E12: =IFERROR(AGGREGATE(15,6,ROW('Input Transaksi'!$B$5:$B$5000)/('Input Transaksi'!$B$5:$B$5000="DIY"),ROWS($E$5:E12)),"")
A13: =IF($E13="","",INDEX('Input Transaksi'!$A:$A,$E13)) | B13: =IF($E13="","",INDEX('Input Transaksi'!$D:$D,$E13)) | C13: =IF($E13="","",INDEX('Input Transaksi'!$E:$E,$E13)) | D13: =IF($E13="","",INDEX('Input Transaksi'!$F:$F,$E13)) | E13: =IFERROR(AGGREGATE(15,6,ROW('Input Transaksi'!$B$5:$B$5000)/('Input Transaksi'!$B$5:$B$5000="DIY"),ROWS($E$5:E13)),"")
A14: =IF($E14="","",INDEX('Input Transaksi'!$A:$A,$E14)) | B14: =IF($E14="","",INDEX('Input Transaksi'!$D:$D,$E14)) | C14: =IF($E14="","",INDEX('Input Transaksi'!$E:$E,$E14)) | D14: =IF($E14="","",INDEX('Input Transaksi'!$F:$F,$E14)) | E14: =IFERROR(AGGREGATE(15,6,ROW('Input Transaksi'!$B$5:$B$5000)/('Input Transaksi'!$B$5:$B$5000="DIY"),ROWS($E$5:E14)),"")
A15: =IF($E15="","",INDEX('Input Transaksi'!$A:$A,$E15)) | B15: =IF($E15="","",INDEX('Input Transaksi'!$D:$D,$E15)) | C15: =IF($E15="","",INDEX('Input Transaksi'!$E:$E,$E15)) | D15: =IF($E15="","",INDEX('Input Transaksi'!$F:$F,$E15)) | E15: =IFERROR(AGGREGATE(15,6,ROW('Input Transaksi'!$B$5:$B$5000)/('Input Transaksi'!$B$5:$B$5000="DIY"),ROWS($E$5:E15)),"")
A16: =IF($E16="","",INDEX('Input Transaksi'!$A:$A,$E16)) | B16: =IF($E16="","",INDEX('Input Transaksi'!$D:$D,$E16)) | C16: =IF($E16="","",INDEX('Input Transaksi'!$E:$E,$E16)) | D16: =IF($E16="","",INDEX('Input Transaksi'!$F:$F,$E16)) | E16: =IFERROR(AGGREGATE(15,6,ROW('Input Transaksi'!$B$5:$B$5000)/('Input Transaksi'!$B$5:$B$5000="DIY"),ROWS($E$5:E16)),"")
... A1000: =IF($E1000="","",INDEX('Input Transaksi'!$A:$A,$E1000)) | B1000: =IF($E1000="","",INDEX('Input Transaksi'!$D:$D,$E1000)) | C1000: =IF($E1000="","",INDEX('Input Transaksi'!$E:$E,$E1000)) | D1000: =IF($E1000="","",INDEX('Input Transaksi'!$F:$F,$E1000)) | E1000: =IFERROR(AGGREGATE(15,6,ROW('Input Transaksi'!$B$5:$B$5000)/('Input Transaksi'!$B$5:$B$5000="DIY"),ROWS($E$5:E1000)),"")

Sheet JCL PEMOGAN
A1: JCL PEMOGAN | F1: Kembali ke Beranda
A2: Wilayah | B2: SELATAN | C2: Total Qty | D2: =SUMIFS('Input Transaksi'!$E$5:$E$5000,'Input Transaksi'!$B$5:$B$5000,"JCL PEMOGAN") | E2: Jumlah Transaksi | F2: =COUNTIF('Input Transaksi'!$B$5:$B$5000,"JCL PEMOGAN")
A4: Tanggal | B4: Item | C4: Qty Keluar | D4: Catatan | E4: RowRef
A5: =IF($E5="","",INDEX('Input Transaksi'!$A:$A,$E5)) | B5: =IF($E5="","",INDEX('Input Transaksi'!$D:$D,$E5)) | C5: =IF($E5="","",INDEX('Input Transaksi'!$E:$E,$E5)) | D5: =IF($E5="","",INDEX('Input Transaksi'!$F:$F,$E5)) | E5: =IFERROR(AGGREGATE(15,6,ROW('Input Transaksi'!$B$5:$B$5000)/('Input Transaksi'!$B$5:$B$5000="JCL PEMOGAN"),ROWS($E$5:E5)),"")
A6: =IF($E6="","",INDEX('Input Transaksi'!$A:$A,$E6)) | B6: =IF($E6="","",INDEX('Input Transaksi'!$D:$D,$E6)) | C6: =IF($E6="","",INDEX('Input Transaksi'!$E:$E,$E6)) | D6: =IF($E6="","",INDEX('Input Transaksi'!$F:$F,$E6)) | E6: =IFERROR(AGGREGATE(15,6,ROW('Input Transaksi'!$B$5:$B$5000)/('Input Transaksi'!$B$5:$B$5000="JCL PEMOGAN"),ROWS($E$5:E6)),"")
A7: =IF($E7="","",INDEX('Input Transaksi'!$A:$A,$E7)) | B7: =IF($E7="","",INDEX('Input Transaksi'!$D:$D,$E7)) | C7: =IF($E7="","",INDEX('Input Transaksi'!$E:$E,$E7)) | D7: =IF($E7="","",INDEX('Input Transaksi'!$F:$F,$E7)) | E7: =IFERROR(AGGREGATE(15,6,ROW('Input Transaksi'!$B$5:$B$5000)/('Input Transaksi'!$B$5:$B$5000="JCL PEMOGAN"),ROWS($E$5:E7)),"")
A8: =IF($E8="","",INDEX('Input Transaksi'!$A:$A,$E8)) | B8: =IF($E8="","",INDEX('Input Transaksi'!$D:$D,$E8)) | C8: =IF($E8="","",INDEX('Input Transaksi'!$E:$E,$E8)) | D8: =IF($E8="","",INDEX('Input Transaksi'!$F:$F,$E8)) | E8: =IFERROR(AGGREGATE(15,6,ROW('Input Transaksi'!$B$5:$B$5000)/('Input Transaksi'!$B$5:$B$5000="JCL PEMOGAN"),ROWS($E$5:E8)),"")
A9: =IF($E9="","",INDEX('Input Transaksi'!$A:$A,$E9)) | B9: =IF($E9="","",INDEX('Input Transaksi'!$D:$D,$E9)) | C9: =IF($E9="","",INDEX('Input Transaksi'!$E:$E,$E9)) | D9: =IF($E9="","",INDEX('Input Transaksi'!$F:$F,$E9)) | E9: =IFERROR(AGGREGATE(15,6,ROW('Input Transaksi'!$B$5:$B$5000)/('Input Transaksi'!$B$5:$B$5000="JCL PEMOGAN"),ROWS($E$5:E9)),"")
A10: =IF($E10="","",INDEX('Input Transaksi'!$A:$A,$E10)) | B10: =IF($E10="","",INDEX('Input Transaksi'!$D:$D,$E10)) | C10: =IF($E10="","",INDEX('Input Transaksi'!$E:$E,$E10)) | D10: =IF($E10="","",INDEX('Input Transaksi'!$F:$F,$E10)) | E10: =IFERROR(AGGREGATE(15,6,ROW('Input Transaksi'!$B$5:$B$5000)/('Input Transaksi'!$B$5:$B$5000="JCL PEMOGAN"),ROWS($E$5:E10)),"")
A11: =IF($E11="","",INDEX('Input Transaksi'!$A:$A,$E11)) | B11: =IF($E11="","",INDEX('Input Transaksi'!$D:$D,$E11)) | C11: =IF($E11="","",INDEX('Input Transaksi'!$E:$E,$E11)) | D11: =IF($E11="","",INDEX('Input Transaksi'!$F:$F,$E11)) | E11: =IFERROR(AGGREGATE(15,6,ROW('Input Transaksi'!$B$5:$B$5000)/('Input Transaksi'!$B$5:$B$5000="JCL PEMOGAN"),ROWS($E$5:E11)),"")
A12: =IF($E12="","",INDEX('Input Transaksi'!$A:$A,$E12)) | B12: =IF($E12="","",INDEX('Input Transaksi'!$D:$D,$E12)) | C12: =IF($E12="","",INDEX('Input Transaksi'!$E:$E,$E12)) | D12: =IF($E12="","",INDEX('Input Transaksi'!$F:$F,$E12)) | E12: =IFERROR(AGGREGATE(15,6,ROW('Input Transaksi'!$B$5:$B$5000)/('Input Transaksi'!$B$5:$B$5000="JCL PEMOGAN"),ROWS($E$5:E12)),"")
A13: =IF($E13="","",INDEX('Input Transaksi'!$A:$A,$E13)) | B13: =IF($E13="","",INDEX('Input Transaksi'!$D:$D,$E13)) | C13: =IF($E13="","",INDEX('Input Transaksi'!$E:$E,$E13)) | D13: =IF($E13="","",INDEX('Input Transaksi'!$F:$F,$E13)) | E13: =IFERROR(AGGREGATE(15,6,ROW('Input Transaksi'!$B$5:$B$5000)/('Input Transaksi'!$B$5:$B$5000="JCL PEMOGAN"),ROWS($E$5:E13)),"")
A14: =IF($E14="","",INDEX('Input Transaksi'!$A:$A,$E14)) | B14: =IF($E14="","",INDEX('Input Transaksi'!$D:$D,$E14)) | C14: =IF($E14="","",INDEX('Input Transaksi'!$E:$E,$E14)) | D14: =IF($E14="","",INDEX('Input Transaksi'!$F:$F,$E14)) | E14: =IFERROR(AGGREGATE(15,6,ROW('Input Transaksi'!$B$5:$B$5000)/('Input Transaksi'!$B$5:$B$5000="JCL PEMOGAN"),ROWS($E$5:E14)),"")
A15: =IF($E15="","",INDEX('Input Transaksi'!$A:$A,$E15)) | B15: =IF($E15="","",INDEX('Input Transaksi'!$D:$D,$E15)) | C15: =IF($E15="","",INDEX('Input Transaksi'!$E:$E,$E15)) | D15: =IF($E15="","",INDEX('Input Transaksi'!$F:$F,$E15)) | E15: =IFERROR(AGGREGATE(15,6,ROW('Input Transaksi'!$B$5:$B$5000)/('Input Transaksi'!$B$5:$B$5000="JCL PEMOGAN"),ROWS($E$5:E15)),"")
A16: =IF($E16="","",INDEX('Input Transaksi'!$A:$A,$E16)) | B16: =IF($E16="","",INDEX('Input Transaksi'!$D:$D,$E16)) | C16: =IF($E16="","",INDEX('Input Transaksi'!$E:$E,$E16)) | D16: =IF($E16="","",INDEX('Input Transaksi'!$F:$F,$E16)) | E16: =IFERROR(AGGREGATE(15,6,ROW('Input Transaksi'!$B$5:$B$5000)/('Input Transaksi'!$B$5:$B$5000="JCL PEMOGAN"),ROWS($E$5:E16)),"")
... A1000: =IF($E1000="","",INDEX('Input Transaksi'!$A:$A,$E1000)) | B1000: =IF($E1000="","",INDEX('Input Transaksi'!$D:$D,$E1000)) | C1000: =IF($E1000="","",INDEX('Input Transaksi'!$E:$E,$E1000)) | D1000: =IF($E1000="","",INDEX('Input Transaksi'!$F:$F,$E1000)) | E1000: =IFERROR(AGGREGATE(15,6,ROW('Input Transaksi'!$B$5:$B$5000)/('Input Transaksi'!$B$5:$B$5000="JCL PEMOGAN"),ROWS($E$5:E1000)),"")

Sheet JCL AYANI
A1: JCL AYANI | F1: Kembali ke Beranda
A2: Wilayah | B2: UTARA | C2: Total Qty | D2: =SUMIFS('Input Transaksi'!$E$5:$E$5000,'Input Transaksi'!$B$5:$B$5000,"JCL AYANI") | E2: Jumlah Transaksi | F2: =COUNTIF('Input Transaksi'!$B$5:$B$5000,"JCL AYANI")
A4: Tanggal | B4: Item | C4: Qty Keluar | D4: Catatan | E4: RowRef
A5: =IF($E5="","",INDEX('Input Transaksi'!$A:$A,$E5)) | B5: =IF($E5="","",INDEX('Input Transaksi'!$D:$D,$E5)) | C5: =IF($E5="","",INDEX('Input Transaksi'!$E:$E,$E5)) | D5: =IF($E5="","",INDEX('Input Transaksi'!$F:$F,$E5)) | E5: =IFERROR(AGGREGATE(15,6,ROW('Input Transaksi'!$B$5:$B$5000)/('Input Transaksi'!$B$5:$B$5000="JCL AYANI"),ROWS($E$5:E5)),"")
A6: =IF($E6="","",INDEX('Input Transaksi'!$A:$A,$E6)) | B6: =IF($E6="","",INDEX('Input Transaksi'!$D:$D,$E6)) | C6: =IF($E6="","",INDEX('Input Transaksi'!$E:$E,$E6)) | D6: =IF($E6="","",INDEX('Input Transaksi'!$F:$F,$E6)) | E6: =IFERROR(AGGREGATE(15,6,ROW('Input Transaksi'!$B$5:$B$5000)/('Input Transaksi'!$B$5:$B$5000="JCL AYANI"),ROWS($E$5:E6)),"")
A7: =IF($E7="","",INDEX('Input Transaksi'!$A:$A,$E7)) | B7: =IF($E7="","",INDEX('Input Transaksi'!$D:$D,$E7)) | C7: =IF($E7="","",INDEX('Input Transaksi'!$E:$E,$E7)) | D7: =IF($E7="","",INDEX('Input Transaksi'!$F:$F,$E7)) | E7: =IFERROR(AGGREGATE(15,6,ROW('Input Transaksi'!$B$5:$B$5000)/('Input Transaksi'!$B$5:$B$5000="JCL AYANI"),ROWS($E$5:E7)),"")
A8: =IF($E8="","",INDEX('Input Transaksi'!$A:$A,$E8)) | B8: =IF($E8="","",INDEX('Input Transaksi'!$D:$D,$E8)) | C8: =IF($E8="","",INDEX('Input Transaksi'!$E:$E,$E8)) | D8: =IF($E8="","",INDEX('Input Transaksi'!$F:$F,$E8)) | E8: =IFERROR(AGGREGATE(15,6,ROW('Input Transaksi'!$B$5:$B$5000)/('Input Transaksi'!$B$5:$B$5000="JCL AYANI"),ROWS($E$5:E8)),"")
A9: =IF($E9="","",INDEX('Input Transaksi'!$A:$A,$E9)) | B9: =IF($E9="","",INDEX('Input Transaksi'!$D:$D,$E9)) | C9: =IF($E9="","",INDEX('Input Transaksi'!$E:$E,$E9)) | D9: =IF($E9="","",INDEX('Input Transaksi'!$F:$F,$E9)) | E9: =IFERROR(AGGREGATE(15,6,ROW('Input Transaksi'!$B$5:$B$5000)/('Input Transaksi'!$B$5:$B$5000="JCL AYANI"),ROWS($E$5:E9)),"")
